Workbook

Sheet Plantilla
A1: nombre_proyecto | B1: fuente | C1: creditos_emitidos | D1: url_ficha | E1: fecha_consulta | F1: tipo_territorio | G1: territorio_declarado | H1: id_ant | I1: nombre_ant | J1: municipios_nombre | K1: cod_dane | L1: departamento_ant | M1: area_ha_ant | N1: municipios_adicionales | O1: anio_inicio | P1: evidencia | Q1: confianza | R1: notas
A2: Proyecto Conservación ARLEQUÍN REDD+ | B2: cercarbono | C2: 2025215 | D2: https://registry.cercarbono.com/projects/CDC-22 | E2: 2026-09-20 | F2: Consejo comunitario | G2: ACISANP, COCOILLO, COCOMACER | I2: =IFERROR(VLOOKUP($H2,Resguardos_ANT!$A$2:$F$969,2,FALSE),"") | J2: Canton de San Pablo (CHOCO), Lloro (CHOCO), Certegui (CHOCO) | K2: =IFERROR(VLOOKUP($H2,Resguardos_ANT!$A$2:$F$969,5,FALSE),"") | L2: =IFERROR(VLOOKUP($H2,Resguardos_ANT!$A$2:$F$969,4,FALSE),"") | M2: =IFERROR(VLOOKUP($H2,Resguardos_ANT!$A$2:$F$969,6,FALSE),"") | N2: 82626 | O2: 2015 | P2: In the municipalities of Canton de San Pablo, Lloro and Certegui ... protect 82.626 hectares of tropical rainforest | Q2: alta | R2: 3 consejos comunitarios, 3 municipios. Proyecto multicomponente (REDD+ mas reforestacion, agricultura, estufas, turismo)
A3: Manejo Sostenible de los Bosques Aplicado en el Oriente | B3: cercarbono | C3: 266413 | D3: https://registry.cercarbono.com/projects/CDC-28 | E3: 2026-09-20 | F3: Otro | G3: Jurisdiccion CORNARE, Oriente antioqueno | I3: =IFERROR(VLOOKUP($H3,Resguardos_ANT!$A$2:$F$969,2,FALSE),"") | K3: =IFERROR(VLOOKUP($H3,Resguardos_ANT!$A$2:$F$969,5,FALSE),"") | L3: =IFERROR(VLOOKUP($H3,Resguardos_ANT!$A$2:$F$969,4,FALSE),"") | M3: =IFERROR(VLOOKUP($H3,Resguardos_ANT!$A$2:$F$969,6,FALSE),"") | O3: 2017 | P3: is developed in the CORNARE jurisdiction which is located in Antioquia department | Q3: baja | R3: NO DETERMINABLE: CORNARE cubre ~26 municipios y la ficha no nombra ninguno. Esquema BanCO2. Dejar fuera o buscar el PDD completo
A4: Makaro Ap+ro | B4: cercarbono | C4: 828348 | D4: https://registry.cercarbono.com/projects/CDC-52 | E4: 2026-09-20 | F4: Resguardo indigena | G4: no nombrado en la ficha | I4: =IFERROR(VLOOKUP($H4,Resguardos_ANT!$A$2:$F$969,2,FALSE),"") | J4: Mitu (VAUPES) | K4: =IFERROR(VLOOKUP($H4,Resguardos_ANT!$A$2:$F$969,5,FALSE),"") | L4: =IFERROR(VLOOKUP($H4,Resguardos_ANT!$A$2:$F$969,4,FALSE),"") | M4: =IFERROR(VLOOKUP($H4,Resguardos_ANT!$A$2:$F$969,6,FALSE),"") | O4: 2018 | P4: Colombia, Vaupes, Mitu | Q4: alta | R4: Municipio explicito al final de la descripcion; el resguardo no se nombra
A5: BAKA ROKARIRE ~IA TIR+~DITO | B5: cercarbono | C5: 1538581 | D5: https://registry.cercarbono.com/projects/CDC-53 | E5: 2026-09-20 | F5: No determinado | G5: no nombrado | I5: =IFERROR(VLOOKUP($H5,Resguardos_ANT!$A$2:$F$969,2,FALSE),"") | K5: =IFERROR(VLOOKUP($H5,Resguardos_ANT!$A$2:$F$969,5,FALSE),"") | L5: =IFERROR(VLOOKUP($H5,Resguardos_ANT!$A$2:$F$969,4,FALSE),"") | M5: =IFERROR(VLOOKUP($H5,Resguardos_ANT!$A$2:$F$969,6,FALSE),"") | O5: 2018 | P5: Colombia, Vaupes, Vaupes | Q5: media | R5: Solo departamento. 'Vaupes, Vaupes' puede referirse al area no municipalizada; verificar en el PDD
A6: Awakadaa Matsiadali | B6: cercarbono | C6: 1631346 | D6: https://registry.cercarbono.com/projects/CDC-55 | E6: 2026-09-20 | F6: Resguardo indigena | G6: no nombrado en la ficha | I6: =IFERROR(VLOOKUP($H6,Resguardos_ANT!$A$2:$F$969,2,FALSE),"") | J6: Inirida (GUAINIA) | K6: =IFERROR(VLOOKUP($H6,Resguardos_ANT!$A$2:$F$969,5,FALSE),"") | L6: =IFERROR(VLOOKUP($H6,Resguardos_ANT!$A$2:$F$969,4,FALSE),"") | M6: =IFERROR(VLOOKUP($H6,Resguardos_ANT!$A$2:$F$969,6,FALSE),"") | O6: 2018 | P6: Colombia, Guainia, Inirida | Q6: alta | R6: Municipio explicito
A7: Jocū Bucūrō Apūrō | B7: cercarbono | C7: 127581 | D7: https://registry.cercarbono.com/projects/CDC-56 | E7: 2026-09-20 | F7: No determinado | I7: =IFERROR(VLOOKUP($H7,Resguardos_ANT!$A$2:$F$969,2,FALSE),"") | K7: =IFERROR(VLOOKUP($H7,Resguardos_ANT!$A$2:$F$969,5,FALSE),"") | L7: =IFERROR(VLOOKUP($H7,Resguardos_ANT!$A$2:$F$969,4,FALSE),"") | M7: =IFERROR(VLOOKUP($H7,Resguardos_ANT!$A$2:$F$969,6,FALSE),"") | O7: 2018 | Q7: baja | R7: SIN UBICACION en la ficha: solo dice 'Colombian Amazon region'. Requiere el PDD
A8: BANAKALE - ISIMALI REDD+ | B8: cercarbono | C8: 287597 | D8: https://registry.cercarbono.com/projects/CDC-60 | E8: 2026-09-20 | F8: Resguardo indigena | G8: Santa Teresita del Tuparro; San Luis del Tomo | I8: =IFERROR(VLOOKUP($H8,Resguardos_ANT!$A$2:$F$969,2,FALSE),"") | J8: Cumaribo (VICHADA) | K8: =IFERROR(VLOOKUP($H8,Resguardos_ANT!$A$2:$F$969,5,FALSE),"") | L8: =IFERROR(VLOOKUP($H8,Resguardos_ANT!$A$2:$F$969,4,FALSE),"") | M8: =IFERROR(VLOOKUP($H8,Resguardos_ANT!$A$2:$F$969,6,FALSE),"") | O8: 2016 | P8: sustainable management system for the forests of the Santa Teresita del Tuparro and San Luis del Tomo indigenous reserves | Q8: media | R8: Los dos resguardos no aparecen con ese nombre en la capa ANT; los resguardos del Tuparro registrados estan en 99773 Cumaribo (Vichada). Verificar
A9: COCOMAN FRONTERA REDD+ | B9: cercarbono | C9: 3730876 | D9: https://registry.cercarbono.com/projects/CDC-61 | E9: 2026-09-20 | F9: Consejo comunitario | G9: Los Marlin (Jurado); COCOMAN (Novita) | I9: =IFERROR(VLOOKUP($H9,Resguardos_ANT!$A$2:$F$969,2,FALSE),"") | J9: Jurado (CHOCO), Novita (CHOCO) | K9: =IFERROR(VLOOKUP($H9,Resguardos_ANT!$A$2:$F$969,5,FALSE),"") | L9: =IFERROR(VLOOKUP($H9,Resguardos_ANT!$A$2:$F$969,4,FALSE),"") | M9: =IFERROR(VLOOKUP($H9,Resguardos_ANT!$A$2:$F$969,6,FALSE),"") | N9: 147000 | O9: 2016 | P9: is developed in the department of Choco, specifically in the municipalities of Jurado and Novita | Q9: alta | R9: 2 municipios no contiguos
A10: Planeta agradecido con el Resguardo Indígena Bajo R... | B10: cercarbono | C10: 5662606 | D10: https://registry.cercarbono.com/projects/CDC-64 | E10: 2026-09-20 | F10: Resguardo indigena | G10: Bajo Rio Guainia y Rio Negro | H10: 10372 | I10: =IFERROR(VLOOKUP($H10,Resguardos_ANT!$A$2:$F$969,2,FALSE),"") -> Resguardo Indígena Bajo Rio Guainia Y Rio Negro | J10: Inirida (GUAINIA) | K10: =IFERROR(VLOOKUP($H10,Resguardos_ANT!$A$2:$F$969,5,FALSE),"") -> 94001 | L10: =IFERROR(VLOOKUP($H10,Resguardos_ANT!$A$2:$F$969,4,FALSE),"") -> 94 | M10: =IFERROR(VLOOKUP($H10,Resguardos_ANT!$A$2:$F$969,6,FALSE),"") -> 759200 | N10: 466757 | O10: 2018 | P10: is developed in 61.48% of the total area of the territory of the Indigenous Resguardo Bajo Rio Guainia y Rio Negro | Q10: alta | R10: Fase I. Area = 61,48% de las 759.200 ha del resguardo (ANT ID 10372). Periodo de acreditacion 2018-01-01/2037-12-31
A11: Manejo Sostenible de los Bosques Aplicado al Predio | B11: cercarbono | C11: 4947 | D11: https://registry.cercarbono.com/projects/CDC-65 | E11: 2026-09-20 | F11: Predio privado | G11: Predio Santa Ana, vereda El Popal | I11: =IFERROR(VLOOKUP($H11,Resguardos_ANT!$A$2:$F$969,2,FALSE),"") | J11: Sonson (ANTIOQUIA) | K11: =IFERROR(VLOOKUP($H11,Resguardos_ANT!$A$2:$F$969,5,FALSE),"") | L11: =IFERROR(VLOOKUP($H11,Resguardos_ANT!$A$2:$F$969,4,FALSE),"") | M11: =IFERROR(VLOOKUP($H11,Resguardos_ANT!$A$2:$F$969,6,FALSE),"") | O11: 2014 | P11: applied to the Santa Ana property, El Popal village, Sonson Municipality | Q11: alta | R11: Predio individual bajo esquema BanCO2
A12: Proyecto REDD+ Zona Isana y Surubi | B12: cercarbono | C12: 1112174 | D12: https://registry.cercarbono.com/projects/CDC-67 | E12: 2026-09-20 | F12: Resguardo indigena | G12: Gran Resguardo del Vaupes | H12: 10743 | I12: =IFERROR(VLOOKUP($H12,Resguardos_ANT!$A$2:$F$969,2,FALSE),"") -> Resguardo Indígena Vaupes | J12: Mitu (VAUPES) | K12: =IFERROR(VLOOKUP($H12,Resguardos_ANT!$A$2:$F$969,5,FALSE),"") -> 97001 | L12: =IFERROR(VLOOKUP($H12,Resguardos_ANT!$A$2:$F$969,4,FALSE),"") -> 97 | M12: =IFERROR(VLOOKUP($H12,Resguardos_ANT!$A$2:$F$969,6,FALSE),"") -> 3955168.9 | N12: 133806 | O12: 2018 | P12: will be developed in 133.806,35 hectares of the territory of the Great Vaupes Indigenous Reservation | Q12: media | R12: El Gran Resguardo del Vaupes (ANT 10743) tiene 3.955.168 ha y abarca varios municipios; el proyecto ocupa 133.806 ha. Municipio ANT = 97001 Mitu, pero el area del proyecto puede caer en otro
A13: REDD+ PAZCÍFICO | B13: cercarbono | C13: 3753988 | D13: https://registry.cercarbono.com/projects/CDC-89 | E13: 2026-09-20 | F13: Consejo comunitario | G13: Unicosta; Prodefensa del Rio Tapaje; Guapi Abajo; Cuenca del Rio Iscuande | I13: =IFERROR(VLOOKUP($H13,Resguardos_ANT!$A$2:$F$969,2,FALSE),"") | J13: El Charco (NARINO) | K13: =IFERROR(VLOOKUP($H13,Resguardos_ANT!$A$2:$F$969,5,FALSE),"") | L13: =IFERROR(VLOOKUP($H13,Resguardos_ANT!$A$2:$F$969,4,FALSE),"") | M13: =IFERROR(VLOOKUP($H13,Resguardos_ANT!$A$2:$F$969,6,FALSE),"") | O13: 2015 | P13: involves the community councils of Unicosta, Prodefensa del Rio Tapaje, Guapi Abajo and Cuenca del Rio Iscuande ... Colombia, Narino, El Charco | Q13: media | R13: Los consejos apuntan a mas de un municipio y a dos departamentos: Prodefensa del Rio Tapaje (El Charco, Narino), Cuenca del Rio Iscuande (Santa Barbara, Narino) y Guapi Abajo (Guapi, CAUCA). La etiqueta de la ficha solo dice Narino. Solo se asigna El Charco; los otros tres quedan pendientes de verificar en el PDD
A14: Pedeguita y Mancilla REDD+ | B14: cercarbono | C14: 1443877 | D14: https://registry.cercarbono.com/projects/CDC-99 | E14: 2026-09-20 | F14: Consejo comunitario | G14: Pedeguita y Mancilla | I14: =IFERROR(VLOOKUP($H14,Resguardos_ANT!$A$2:$F$969,2,FALSE),"") | J14: Riosucio (CHOCO), Carmen del Darien (CHOCO), Belen de Bajira (CHOCO) | K14: =IFERROR(VLOOKUP($H14,Resguardos_ANT!$A$2:$F$969,5,FALSE),"") | L14: =IFERROR(VLOOKUP($H14,Resguardos_ANT!$A$2:$F$969,4,FALSE),"") | M14: =IFERROR(VLOOKUP($H14,Resguardos_ANT!$A$2:$F$969,6,FALSE),"") | O14: 2020 | P14: located in the municipalities of Riosucio, Carmen del Darien and Belen de Bajira, in the department of Choco | Q14: alta | R14: OJO: Belen de Bajira no es municipio DANE vigente (territorio en disputa Choco/Antioquia); si no resuelve, asignar a Riosucio y Carmen del Darien
A15: PITUGUCAJUDE | B15: cercarbono | C15: 1057980 | D15: https://registry.cercarbono.com/projects/CDC-100 | E15: 2026-09-20 | F15: Resguardo indigena | G15: no nombrado en la ficha | I15: =IFERROR(VLOOKUP($H15,Resguardos_ANT!$A$2:$F$969,2,FALSE),"") | J15: Mitu (VAUPES) | K15: =IFERROR(VLOOKUP($H15,Resguardos_ANT!$A$2:$F$969,5,FALSE),"") | L15: =IFERROR(VLOOKUP($H15,Resguardos_ANT!$A$2:$F$969,4,FALSE),"") | M15: =IFERROR(VLOOKUP($H15,Resguardos_ANT!$A$2:$F$969,6,FALSE),"") | O15: 2018 | P15: Colombia, Vaupes, Mitu | Q15: alta | R15: Municipio explicito
A16: Proyecto Agrupado YAAWI IIPANA REDD+ | B16: cercarbono | C16: 6710197 | D16: https://registry.cercarbono.com/projects/CDC-102 | E16: 2026-09-20 | F16: Resguardo indigena | G16: Morichal Viejo, Santa Rosa, Cerro Cocuy, Santa Cruz, Cano Danta y otros | H16: 10413 | I16: =IFERROR(VLOOKUP($H16,Resguardos_ANT!$A$2:$F$969,2,FALSE),"") -> Resguardo Indígena Puinave y Curripaco de Morichal Viejo - Santa Rosa, Cerro Cucuy, Santa Cruz, Caño Danta | K16: =IFERROR(VLOOKUP($H16,Resguardos_ANT!$A$2:$F$969,5,FALSE),"") -> 95025 | L16: =IFERROR(VLOOKUP($H16,Resguardos_ANT!$A$2:$F$969,4,FALSE),"") -> 95 | M16: =IFERROR(VLOOKUP($H16,Resguardos_ANT!$A$2:$F$969,6,FALSE),"") -> 670000 | N16: 671145 | O16: 2016 | P16: conservation and protection of 671.145 [ha] ... proposed by the Morichal Viejo, Santa Rosa, Cerro Cocuy, Santa Cruz, Cano Danta and others Indigenous Reserve | Q16: alta | R16: Coincidencia casi exacta de area: ANT 10413 registra 670.000 ha. ANT lo asigna a municipio 95025 (Guaviare), pero los parajes nombrados son de Guainia: el resguardo cruza el limite. VERIFICAR antes de fijar municipio
A17: PROYECTO REDD+ PAZCÍFICO SUR | B17: cercarbono | C17: 3671289 | D17: https://registry.cercarbono.com/projects/CDC-114 | E17: 2026-09-20 | F17: Consejo comunitario | G17: 18 comunidades afrodescendientes | I17: =IFERROR(VLOOKUP($H17,Resguardos_ANT!$A$2:$F$969,2,FALSE),"") | J17: El Charco (NARINO) | K17: =IFERROR(VLOOKUP($H17,Resguardos_ANT!$A$2:$F$969,5,FALSE),"") | L17: =IFERROR(VLOOKUP($H17,Resguardos_ANT!$A$2:$F$969,4,FALSE),"") | M17: =IFERROR(VLOOKUP($H17,Resguardos_ANT!$A$2:$F$969,6,FALSE),"") | N17: 371749 | O17: 2017 | P17: developed in 18 Afrodescendant communities in Departament of Narino ... inside 371.749 hectares | Q17: media | R17: Solo se nombra El Charco al final; 371.749 ha en 18 comunidades abarcan mas municipios de la costa nariniense
A18: CHONTA COROZO REDD+ Project | B18: cercarbono | C18: 783573 | D18: https://registry.cercarbono.com/projects/CDC-117 | E18: 2026-09-20 | F18: Consejo comunitario | G18: Alto Guapi | I18: =IFERROR(VLOOKUP($H18,Resguardos_ANT!$A$2:$F$969,2,FALSE),"") | J18: Guapi (CAUCA) | K18: =IFERROR(VLOOKUP($H18,Resguardos_ANT!$A$2:$F$969,5,FALSE),"") | L18: =IFERROR(VLOOKUP($H18,Resguardos_ANT!$A$2:$F$969,4,FALSE),"") | M18: =IFERROR(VLOOKUP($H18,Resguardos_ANT!$A$2:$F$969,6,FALSE),"") | N18: 93142 | O18: 2017 | P18: collective territories of the Community Council of the Alto Guapi, which is in Guapi municipality, in Cauca department | Q18: alta | R18: Municipio explicito
A19: Cavadacavᵾ Coreivᵾ Jocᵾ Bᵾcᵾro Rẽ, N̄ᵾjẽ N̄ecᵾvã | B19: cercarbono | C19: 1206320 | D19: https://registry.cercarbono.com/projects/CDC-118 | E19: 2026-09-20 | F19: Resguardo indigena | G19: no nombrado en la ficha | I19: =IFERROR(VLOOKUP($H19,Resguardos_ANT!$A$2:$F$969,2,FALSE),"") | J19: San Jose del Guaviare (GUAVIARE) | K19: =IFERROR(VLOOKUP($H19,Resguardos_ANT!$A$2:$F$969,5,FALSE),"") | L19: =IFERROR(VLOOKUP($H19,Resguardos_ANT!$A$2:$F$969,4,FALSE),"") | M19: =IFERROR(VLOOKUP($H19,Resguardos_ANT!$A$2:$F$969,6,FALSE),"") | O19: 2018 | P19: Colombia, Guaviare, San Jose del Guaviare | Q19: alta | R19: Municipio explicito
A20: Planeta Agradecido con el Resguardo indígena Bajo Río | B20: cercarbono | C20: 504276 | D20: https://registry.cercarbono.com/projects/CDC-146 | E20: 2026-09-20 | F20: Resguardo indigena | G20: Bajo Rio Guainia y Rio Negro II | H20: 10372 | I20: =IFERROR(VLOOKUP($H20,Resguardos_ANT!$A$2:$F$969,2,FALSE),"") -> Resguardo Indígena Bajo Rio Guainia Y Rio Negro | J20: Inirida (GUAINIA) | K20: =IFERROR(VLOOKUP($H20,Resguardos_ANT!$A$2:$F$969,5,FALSE),"") -> 94001 | L20: =IFERROR(VLOOKUP($H20,Resguardos_ANT!$A$2:$F$969,4,FALSE),"") -> 94 | M20: =IFERROR(VLOOKUP($H20,Resguardos_ANT!$A$2:$F$969,6,FALSE),"") -> 759200 | N20: 293400.88 | O20: 2022 | P20: is developed in 293.400,88 hectares of the territory of the 'Bajo Rio Guainia y Rio Negro' Indigenous Reservation | Q20: alta | R20: Fase II del mismo resguardo que CDC-64. Con min(anio) el municipio entra por la fase I (2018); la fase II solo suma dosis en la especificacion de intensidad
A21: Proyecto de Conservación UNU-MAI REDD+ | B21: cercarbono | C21: 4593219 | D21: https://registry.cercarbono.com/projects/CDC-148 | E21: 2026-09-20 | F21: Resguardo indigena | G21: Laguna Ninal, Cocuy, Loma Baja y Loma Alta | H21: 10384 | I21: =IFERROR(VLOOKUP($H21,Resguardos_ANT!$A$2:$F$969,2,FALSE),"") -> Resguardo Indígena Puinave y Sikuani de Laguna Niñal, Cocuy, Loma Baja y Loma Alta del Caño Guariben | J21: Inirida (GUAINIA) | K21: =IFERROR(VLOOKUP($H21,Resguardos_ANT!$A$2:$F$969,5,FALSE),"") -> 94001 | L21: =IFERROR(VLOOKUP($H21,Resguardos_ANT!$A$2:$F$969,4,FALSE),"") -> 94 | M21: =IFERROR(VLOOKUP($H21,Resguardos_ANT!$A$2:$F$969,6,FALSE),"") -> 138437.5 | N21: 130404 | O21: 2017 | P21: Indigenous Reserve, located in the municipality of Inirida, department of Guainia ... 130.404 hectares of natural forest | Q21: alta | R21: Municipio explicito y coincidencia con ANT 10384 (138.437,5 ha registradas)
A22: GUAINIA REDD+ PROJECT | B22: cercarbono | C22: 4765619 | D22: https://registry.cercarbono.com/projects/CDC-152 | E22: 2026-09-20 | F22: Resguardo indigena | G22: Almidon La Ceiba; Caranacoa-Yuri Laguna Morocoto; Venado; Paujil-Limonar; Rios Cuiari e Isana | I22: =IFERROR(VLOOKUP($H22,Resguardos_ANT!$A$2:$F$969,2,FALSE),"") | J22: Inirida (GUAINIA) | K22: =IFERROR(VLOOKUP($H22,Resguardos_ANT!$A$2:$F$969,5,FALSE),"") | L22: =IFERROR(VLOOKUP($H22,Resguardos_ANT!$A$2:$F$969,4,FALSE),"") | M22: =IFERROR(VLOOKUP($H22,Resguardos_ANT!$A$2:$F$969,6,FALSE),"") | O22: 2018 | P22: en los Resguardos Indigenas Almidon La Ceiba, Caranacoa-Yuri Laguna Morocoto, Venado, Paujil-Limonar y Rios Cuiari e Isana ... Departamento del Guainia | Q22: media | R22: CINCO resguardos: ANT 10373 (94001), 10381 (94001), 10388 (94001), 10391 (94887). Cuatro en Inirida y uno en 94887. No hay un solo id_ant; registrar municipios 94001 y 94887
A23: Awakadaa Jiduaa | B23: cercarbono | C23: 1701850 | D23: https://registry.cercarbono.com/projects/CDC-155 | E23: 2026-09-20 | F23: Resguardo indigena | G23: Tonina, Sejal, San Jose y Otros | H23: 10394 | I23: =IFERROR(VLOOKUP($H23,Resguardos_ANT!$A$2:$F$969,2,FALSE),"") -> Resguardo Indígena Curripaco de Tonina, Sejal, San Jose y Otras | J23: Inirida (GUAINIA) | K23: =IFERROR(VLOOKUP($H23,Resguardos_ANT!$A$2:$F$969,5,FALSE),"") -> 94001 | L23: =IFERROR(VLOOKUP($H23,Resguardos_ANT!$A$2:$F$969,4,FALSE),"") -> 94 | M23: =IFERROR(VLOOKUP($H23,Resguardos_ANT!$A$2:$F$969,6,FALSE),"") -> 853320 | N23: 853320 | O23: 2018 | P23: the second phase of work of the Tonina, Sejal, San Jose and Others Indigenous Reservation, created by INCORA resolution 079 of 1989 | Q23: alta | R23: Coincidencia exacta con ANT 10394 (853.320 ha, municipio 94001). Es SEGUNDA FASE: buscar si la primera esta registrada aparte
A25: EJEMPLO - no editar ni usar | B25: cercarbono | C25: 999999 | D25: https://registro.cercarbono.com/... | E25: 2026-09-20 | F25: Resguardo indigena | G25: Resguardo Indigena Wacoyo | H25: 10254 | N25: 99524, 99001 | O25: 2019 | P25: PDD seccion 1.12: el area del proyecto se ubica en el resguardo X, municipio Y | Q25: alta | R25: El PDD lista 2 municipios; se registran ambos

Sheet Instrucciones
A1: PLANTILLA DE RECUPERACION MANUAL DE UBICACION
A3: Alcance | B3: Los 22 proyectos REDD+ de Cercarbono con creditos emitidos > 0 (47.407.872 tCO2e en total), que hoy no tienen municipio asignado y por tanto estan en el grupo de CONTROL.
B4: Los otros 9 proyectos ccb-redd de Cercarbono tienen 0 creditos: no activaron el mecanismo y no cambian el tratamiento, asi que no entran a esta plantilla.
A6: Colores | B6: GRIS = dato ya cargado, no editar. AMARILLO = rellenar a mano. VERDE = formula, se llena sola.
A8: Como llenar | B8: 1. Abre la ficha publica del proyecto en el registro de Cercarbono y pega la URL en url_ficha.
B9: 2. Anota la fecha de consulta: las fichas cambian y la trazabilidad importa.
B10: 3. Busca en el PDD el territorio donde opera (resguardo, consejo comunitario o predio) y escribelo TAL CUAL en territorio_declarado.
B11: 4. Busca ese territorio en la hoja Resguardos_ANT filtrando por PUEBLO y DEPARTAMENTO, no por nombre: los proyectos NO se llaman como el resguardo, y el empate por similitud da falsos positivos.
B12: 5. Copia el ID de la ANT en id_ant. Las columnas verdes se llenan solas.
B13: 6. Si el PDD nombra mas municipios que el que trae la ANT, listalos en municipios_adicionales separados por coma. Un resguardo grande abarca varios.
B14: 7. Copia en evidencia la frase del PDD que sustenta la ubicacion. Es lo que vas a citar si preguntan por un municipio concreto en la sustentacion.
A16: Confianza | B16: alta = el PDD lista municipios explicitamente, o el territorio esta identificado sin ambiguedad en la ANT
B17: media = solo hay departamento y pueblo, y el resguardo se dedujo entre pocos candidatos
B18: baja = ubicacion aproximada o inferida; NO debe entrar a la especificacion principal
A20: Regla de oro | B20: Ante la duda, deja la fila vacia. Un municipio tratado por error fija una cohorte espuria y sesga el estimador; un faltante solo atenua hacia cero, que es la direccion en la que ya esta documentado el sesgo.
A22: Fuente ANT | B22: Resguardo Indigena Formalizado, Agencia Nacional de Tierras, portal de Datos Abiertos. 968 resguardos. Descargado por el usuario.
A23: Fuente creditos | B23: OffsetsDB (CarbonPlan), campo issued, registry=cercarbono, protocol=ccb-redd.

Sheet Resguardos_ANT
A1: ID | B1: NOMBRE | C1: PUEBLO | D1: DEPARTAMENTO | E1: MUNICIPIO | F1: AREA_TOTAL_ACTOS_ADMIN
A2: 10254 | B2: Resguardo Indígena Embera Buchado Amparrado | C2: EMBERA | D2: 27 | E2: 27099 | F2: 8530
A3: 10135 | B3: Resguardo Indígena Paez de Nasa Kiwe | C3: PAEZ | D3: 18 | E3: 18592 | F3: 1602.8693
A4: 10138 | B4: Resguardo Indígena Coreguaje Asentada en la Regiones De Puerto Naranjo, Peñas Rojas, Cuerazo, El Diamante | C4: COREGUAJE | D4: 18 | E4: 18756 | F4: 3618.9794
A5: 10303 | B5: Resguardo Indígena Embera de Peña Blanca - Rio Truando | C5: EMBERA KATIO | D5: 27 | E5: 27615 | F5: 58180
A6: 10273 | B6: Resguardo Indígena Embera-Katio de Playalta, El Veinte y El Noventa | C6: EMBERA KATIO | D6: 27 | E6: QUIBDO | F6: 4977.3288
A7: 10102 | B7: Resguardo Unido U´Wa Cubara De Tunebo | C7: U´WA | D7: 15 | E7: 15223 | F7: 281431
A8: 10792 | B8: Resguardo Indígena Omaga | C8: ZENÚ | D8: 05 | E8: 05120 | F8: 27.7693
A9: 11642 | B9: Resguardo Indígena Vinollanogrande | C9: PIJAO | D9: 73 | E9: 73675 | F9: 40.6654
A10: 10383 | B10: Resguardo Indígena Guahibo -Puinave de Laguna Curvina - Sapuara | C10: GUAHIBO PUINAVE | D10: 94 | E10: 94343 | F10: 3350
A11: 10756 | B11: Resguardo Indígena Piapoco de Kawaneruba | C11: PIAPOCO | D11: 99 | E11: 99773 | F11: 11267.225
A12: 10912 | B12: Resguardo Indígena San Miguel | C12: NASA | D12: 41 | E12: 41396 | F12: 316.2468
A13: 10652 | B13: Resguardo Indígena Pijao de Hilarquito | C13: PIJAO | D13: 73 | E13: 73217 | F13: 105.4358
... A271: 11012 | B271: Resguardo Indígena Yachay Wasi | C271: YANACONA | D271: 86 | E271: 86001 | F271: 42.7045
A272: 11015 | B272: Cabildo Indígena Valle Hermoso | D272: 86 | E272: 86320 | F272: 16.7727
A273: 10601 | B273: Resguardo Inga de San Miguel De La Castellana | C273: INGA | D273: 86 | E273: 86885 | F273: 505.6029
A274: 10149 | B274: Resguardo Indígena Nasa We' Sx Kiwe La Gaitana | C274: NASA | D274: 18 | E274: 18001 | F274: 145.298
A275: 10591 | B275: Resguardo Indígena Embera Chami La Italia | C275: EMBERA CHAMI | D275: 86 | E275: 86865 | F275: 736.3184
A276: 10009 | B276: Resguardo Indígena de Mocagua | C276: TICUNA | D276: 91 | E276: 91001 | F276: 46785.652
A277: 10939 | B277: Resguardo Indígena Nukat Maleiwua (Bendicion De Dios) | C277: WAYUU | D277: 44 | E277: 44430 | F277: 375.6576
A278: 10004 | B278: Resguardo Indígena Yukuna-Cubeo de Curare Los Ingleses | C278: YUCUNA Y CUBEO | D278: 91 | E278: 91001 | F278: 212320
A279: 10602 | B279: Resguardo Indígena Siona Santa Cruz De Pinuña Blanco | C279: SIONA | D279: 86 | E279: PUERTO ASIS | F279: 1990
A280: 10664 | B280: Resguardo Indígena Pijao de Mesa De Ortega | C280: PIJAO | D280: 73 | E280: 73504 | F280: 341.2439
A281: 10183 | B281: Resguardo Indígena Nasa de Kitek Kiwe | C281: NASA | D281: 19 | E281: 19807 | F281: 41.1603
A282: 10645 | B282: Resguardo Indígena Pijao El Vergel | C282: PIJAO | D282: 73 | E282: 73504 | F282: 51.5441
A283: 10458 | B283: Resguardo Indígena Wayuu Rodeito - El Pozo | C283: WAYUU | D283: 44 | E283: 44378 | F283: 106.843
A284: 10299 | B284: Resguardo Indígena Embera - Eperara de Ordo-Siviru-Aguaclara | C284: EMBERA | D284: 27 | E284: 27077 | F284: 4040
... A404: 10133 | B404: Resguardo Indígena Coreguaje de Maticurú | C404: COREGUAJE | D404: 18 | E404: 18460 | F404: 577.6546
A405: 11154 | B405: Resguardo Indígena Chenche Tunarco del Pueblo Pijao | C405: PIJAO | F405: 193.3489
A406: 10130 | B406: Resguardo Indígena Coreguaje de La Teofila | C406: COREGUAJE | D406: 18 | E406: 18756 | F406: 24049.747
A407: 10472 | B407: Resguardo Indígena Embera-Katio de La Julia | C407: EMBERA KATIO | D407: 50 | E407: 50370 | F407: 208.2435
A408: 10430 | B408: Resguardo Indígena Pickwe Ikh | C408: PAEZ | D408: 41 | E408: 41378 | F408: 468.1675
A409: 10013 | B409: Resguardo Indígena Ticuna, Cocama y Yagua - Ticoya | C409: TICUNA COCAMA YAGUA | D409: 91 | E409: 91540 | F409: 171381.19
A410: 10671 | B410: Resguardo Indígena Pijao Palermo | C410: PIJAO | D410: 73 | E410: 73504 | F410: 128.9141
A411: 10241 | B411: Resguardo Indígena Embera Katio de Abejero | C411: EMBERA KATIO | D411: 27 | E411: 27245 | F411: 230.4825
A412: 10436 | B412: Resguardo Indígena San Jose De Isnos | C412: YANACONA | D412: 41 | E412: 41359 | F412: 108.1781
A413: 10531 | B413: Resguardo Indígena Eperara - Siapidaara de Quebrada Grande | C413: EPERARA SIAPIDARA | D413: 52 | E413: 52696 | F413: 774.0986
A414: 10697 | B414: Resguardo Indígena Tamirco | C414: PIJAO | D414: 73 | E414: 73483 | F414: 230.8793
A415: 11054 | B415: Resguardo Indígena Gran Putumayo | C415: PASTOS | D415: 86 | E415: 86001 | F415: 7.9164
A416: 10197 | B416: Resguardo Indígena Misak Piscitau | C416: MISAK | D416: 19 | E416: 19548 | F416: 59.5772
...
